<?xml version="1.0"?>
<robot xmlns:xacro="http://ros.org/wiki/xacro">
  <xacro:macro name="robotiq_hande" params="prefix origin">
    
    <xacro:property name="param_file" value="$(find robot_arms)/config/gripper/hande_parameters.yaml" />
    <xacro:property name="gripper_props" value="${xacro.load_yaml(param_file)}"/>
    
    <xacro:property name="mass_val" value="${gripper_props['robotiq_hande']['mass']}" />
    <xacro:property name="ixx_val" value="${gripper_props['robotiq_hande']['inertia']['ixx']}" />
    <xacro:property name="upper_limit" value="${gripper_props['robotiq_hande']['limits']['upper_stroke']}" />
    <xacro:property name="max_effort" value="${gripper_props['robotiq_hande']['limits']['max_effort']}" />

    <joint name="${prefix}flange_to_camera_mount" type="fixed">
      <parent link="${origin}"/>
      <child link="${prefix}camera_mount_link"/>
      <origin xyz="0 0 0" rpy="0 0 0"/>
    </joint>

    <link name="${prefix}camera_mount_link">
      <inertial>
        <mass value="0.08"/>
        <origin xyz="0 0.028 0.005" rpy="0 0 0"/>
        <inertia ixx="0.0001" ixy="0.0" ixz="0.0" iyy="0.0001" iyz="0.0" izz="0.0001"/>
      </inertial>
      <visual>
        <origin xyz="0 0 0" rpy="-1.5708 0 0"/>
        <geometry>
          <mesh filename="package://robot_arms/meshes/mount/realsenseURflangeSupport.stl" scale="0.001 0.001 0.001"/>
        </geometry>
        <material name="MountGray">
          <color rgba="0.4 0.4 0.4 1.0"/>
        </material>
      </visual>
      <collision>
        <origin xyz="0 0 0" rpy="-1.5708 0 0"/>
        <geometry>
          <mesh filename="package://robot_arms/meshes/mount/realsenseURflangeSupport.stl" scale="0.001 0.001 0.001"/>
        </geometry>
      </collision>
    </link>

    <gazebo reference="${prefix}camera_mount_link">
      <visual>
        <material>
          <ambient>0.3 0.3 0.3 1.0</ambient>
          <diffuse>0.4 0.4 0.4 1.0</diffuse>
          <specular>0.2 0.2 0.2 1.0</specular>
        </material>
      </visual>
    </gazebo>

    <joint name="${prefix}camera_mount_to_camera" type="fixed">
      <parent link="${prefix}camera_mount_link"/>
      <child link="${prefix}camera_link"/>
      <origin xyz="0 0.0575 0.01145" rpy="0 0 0"/>
    </joint>

    <link name="${prefix}camera_link">
      <inertial>
        <mass value="0.072"/>
        <origin xyz="0 0 0" rpy="0 0 0"/>
        <inertia ixx="0.00005" ixy="0.0" ixz="0.0" iyy="0.00001" iyz="0.0" izz="0.00005"/>
      </inertial>
      <visual>
        <origin xyz="0 0 0" rpy="0 0 0"/>
        <geometry>
          <mesh filename="package://robot_arms/meshes/camera/d435.dae"/>
        </geometry>
      </visual>
      <collision>
        <origin xyz="0 0 0" rpy="0 0 0"/>
        <geometry>
          <box size="0.026 0.090 0.025"/>
        </geometry>
      </collision>
    </link>

    <joint name="${prefix}camera_to_optical" type="fixed">
      <parent link="${prefix}camera_link"/>
      <child link="${prefix}camera_color_optical_frame"/>
      <origin xyz="0 0 0" rpy="-1.5708 0 -1.5708"/>
    </joint>
    <link name="${prefix}camera_color_optical_frame"/>

    <joint name="${prefix}base_to_gripper" type="fixed">
      <origin rpy="0 0 0" xyz="0 0 0.005"/>
      <parent link="${origin}"/>
      <child link="${prefix}base_link"/>
    </joint>

    <link name="${prefix}base_link">
      <inertial>
        <origin xyz="0 0 0.046" rpy="0 0 0"/>
        <mass value="${mass_val}"/>
        <inertia ixx="${ixx_val}" ixy="0.0" ixz="0.0" iyy="${ixx_val}" iyz="0.0" izz="${ixx_val}"/>
      </inertial>
      <visual>
        <origin xyz="0 0 0" rpy="0 0 0" />
        <geometry>
          <mesh filename="package://robot_arms/meshes/visual/gripper.stl" scale="0.001 0.001 0.001"/>
        </geometry>
        <material name="Black">
          <color rgba="0.1 0.1 0.1 1" />
        </material>
      </visual>
      <collision>
        <origin xyz="0 0 0" rpy="0 0 0" />
        <geometry>
          <mesh filename="package://robot_arms/meshes/collision/gripper.stl" scale="0.001 0.001 0.001"/>
        </geometry>
      </collision>
    </link>

    <link name="${prefix}jaw1_link">
      <inertial>
        <origin xyz="0 0 0" rpy="0 0 0"/>
        <mass value="0.01"/>
        <inertia ixx="0.0001" ixy="0.0" ixz="0.0" iyy="0.0001" iyz="0.0" izz="0.0001"/>
      </inertial>
      <visual>
        <origin rpy="0 0 0" xyz="0 0 0"/>
        <geometry>
          <mesh filename="package://robot_arms/meshes/visual/jaw.stl" scale="0.001 0.001 0.001"/>
        </geometry>
        <material name="grey">
          <color rgba="0.83 0.83 0.83 1" />
        </material>
      </visual>
      <collision>
        <origin rpy="0 0 0" xyz="0 0 0"/>
        <geometry>
          <mesh filename="package://robot_arms/meshes/collision/jaw.stl" scale="0.001 0.001 0.001"/>
        </geometry>
      </collision>
    </link>

    <link name="${prefix}jaw2_link">
      <inertial>
        <origin xyz="0 0 0" rpy="0 0 0"/>
        <mass value="0.01"/>
        <inertia ixx="0.0001" ixy="0.0" ixz="0.0" iyy="0.0001" iyz="0.0" izz="0.0001"/>
      </inertial>
      <visual>
        <origin rpy="0 0 0" xyz="0 0 0"/>
        <geometry>
          <mesh filename="package://robot_arms/meshes/visual/jaw.stl" scale="0.001 0.001 0.001"/>
        </geometry>
        <material name="Grey">
          <color rgba="0.83 0.83 0.83 1" />
        </material>
      </visual>
      <collision>
        <origin rpy="0 0 0" xyz="0 0 0"/>
        <geometry>
          <mesh filename="package://robot_arms/meshes/collision/jaw.stl" scale="0.001 0.001 0.001"/>
        </geometry>
      </collision>
    </link>

    <link name="${prefix}finger1">
      <inertial>
        <origin xyz="0 0 0" rpy="0 0 0"/>
        <mass value="0.01"/>
        <inertia ixx="0.0001" ixy="0.0" ixz="0.0" iyy="0.0001" iyz="0.0" izz="0.0001"/>
      </inertial>
      <visual>
        <origin rpy="0 0 0" xyz="0 0 0"/>
        <geometry>
          <mesh filename="package://robot_arms/meshes/visual/finger.stl" scale="0.001 0.001 0.001"/>
        </geometry>
        <material name="Black">
          <color rgba="0.1 0.1 0.1 1" />
        </material>
      </visual>
      <collision>
        <origin rpy="0 0 0" xyz="0 0 0"/>
        <geometry>
          <mesh filename="package://robot_arms/meshes/collision/finger.stl" scale="0.001 0.001 0.001"/>
        </geometry>
      </collision>
    </link>

    <link name="${prefix}finger2">
      <inertial>
        <origin xyz="0 0 0" rpy="0 0 0"/>
        <mass value="0.01"/>
        <inertia ixx="0.0001" ixy="0.0" ixz="0.0" iyy="0.0001" iyz="0.0" izz="0.0001"/>
      </inertial>
      <visual>
        <origin rpy="0 0 0" xyz="0 0 0"/>
        <geometry>
          <mesh filename="package://robot_arms/meshes/visual/finger.stl" scale="0.001 0.001 0.001"/>
        </geometry>
        <material name="Black">
          <color rgba="0.1 0.1 0.1 1" />
        </material>
      </visual>
      <collision>
        <origin rpy="0 0 0" xyz="0 0 0"/>
        <geometry>
          <mesh filename="package://robot_arms/meshes/collision/finger.stl" scale="0.001 0.001 0.001"/>
        </geometry>
      </collision>
    </link>

    <joint name="${prefix}joint" type="prismatic">
      <origin rpy="0 0 0" xyz="0 0 0.0952"/>
      <parent link="${prefix}base_link"/>
      <child link="${prefix}jaw1_link"/>
      <axis xyz="1 0 0"/>
      <limit effort="${max_effort}" lower="0.0" upper="${upper_limit}" velocity="0.15"/>
    </joint>

    <joint name="${prefix}base_to_${prefix}jaw2_link" type="prismatic">
      <origin rpy="0 0 ${pi}" xyz="0 0 0.0952"/>
      <parent link="${prefix}base_link"/>
      <child link="${prefix}jaw2_link"/>
      <axis xyz="1 0 0"/>
      <limit effort="${max_effort}" lower="0.0" upper="${upper_limit}" velocity="0.15"/>
      <mimic joint="${prefix}joint" multiplier="1" offset="0"/>
    </joint>

    <joint name="${prefix}jaw1_to_finger1" type="fixed">
      <origin rpy="0 0 0" xyz="0 0 0.0325"/>
      <parent link="${prefix}jaw1_link"/>
      <child link="${prefix}finger1"/>
    </joint>

    <joint name="${prefix}jaw2_to_finger2" type="fixed">
      <origin rpy="0 0 0" xyz="0 0 0.0325"/>
      <parent link="${prefix}jaw2_link"/>
      <child link="${prefix}finger2"/>
    </joint>
    
  </xacro:macro>
</robot>